Workbook

Sheet Оценки
A1: Фаза 1. Исходные экспертные оценки
A2: Синим — редактируемые ячейки. Все расчёты на остальных листах пересчитываются автоматически.
A4: Код | B4: Критерий | C4: Тип | D4: Челяпин Л. | G4: Засыпко Д. | J4: Сопельняк А.
D5: п | E5: о | F5: опт | G5: п | H5: о | I5: опт | J5: п | K5: о | L5: опт
A6: C1 | B6: Насколько легко обойтись без интеграций и внешних данных | C6: выгодный | D6: 6 | E6: 8 | F6: 9 | G6: 5 | H6: 6 | I6: 7 | J6: 7 | K6: 7 | L6: 9
A7: C2 | B7: Острота решаемой проблемы для пользователя | C7: выгодный | D7: 7 | E7: 9 | F7: 9 | G7: 8 | H7: 9 | I7: 9 | J7: 5 | K7: 7 | L7: 8
A8: C3 | B8: Потенциал монетизации | C8: выгодный | D8: 6 | E8: 9 | F8: 9 | G8: 5 | H8: 6 | I8: 7 | J8: 7 | K8: 6 | L8: 8
A9: C4 | B9: Простота декомпозиции на Use Cases | C9: выгодный | D9: 3 | E9: 5 | F9: 6 | G9: 6 | H9: 7 | I9: 8 | J9: 7 | K9: 8 | L9: 9
A11: 2. Альтернативы
A12: Код | B12: Концепция
A13: A1 | B13: Общие подписки и бытовые расходы соседей по квартире
A14: A2 | B14: Трекер поломок и ремонтов вещей («паспорт вещи»)
A15: A3 | B15: FocusFlow — планировщик задач по правилам тайм-менеджмента
A16: A4 | B16: Система контроля версий для текстовых документов
A18: 3. Оценки альтернатив по критериям, шкала 1…9
A19: Критерий | B19: Альтернатива | D19: Челяпин Л. | G19: Засыпко Д. | J19: Сопельняк А.
D20: п | E20: о | F20: опт | G20: п | H20: о | I20: опт | J20: п | K20: о | L20: опт
A21: C1 | B21: A1 | D21: 5 | E21: 7 | F21: 9 | G21: 5 | H21: 6 | I21: 8 | J21: 4 | K21: 6 | L21: 7
A22: C1 | B22: A2 | D22: 7 | E22: 9 | F22: 9 | G22: 3 | H22: 5 | I22: 6 | J22: 4 | K22: 6 | L22: 7
A23: C1 | B23: A3 | D23: 6 | E23: 8 | F23: 9 | G23: 2 | H23: 3 | I23: 5 | J23: 1 | K23: 2 | L23: 4
A24: C1 | B24: A4 | D24: 3 | E24: 5 | F24: 7 | G24: 1 | H24: 2 | I24: 3 | J24: 3 | K24: 3 | L24: 4
A25: C2 | B25: A1 | D25: 3 | E25: 6 | F25: 7 | G25: 8 | H25: 9 | I25: 9 | J25: 7 | K25: 9 | L25: 9
A26: C2 | B26: A2 | D26: 1 | E26: 3 | F26: 4 | G26: 4 | H26: 5 | I26: 6 | J26: 4 | K26: 6 | L26: 7
A27: C2 | B27: A3 | D27: 4 | E27: 6 | F27: 8 | G27: 4 | H27: 5 | I27: 7 | J27: 5 | K27: 6 | L27: 8
A28: C2 | B28: A4 | D28: 5 | E28: 7 | F28: 8 | G28: 3 | H28: 4 | I28: 6 | J28: 4 | K28: 5 | L28: 6
A29: C3 | B29: A1 | D29: 3 | E29: 5 | F29: 5 | G29: 6 | H29: 7 | I29: 8 | J29: 6 | K29: 7 | L29: 8
A30: C3 | B30: A2 | D30: 2 | E30: 4 | F30: 5 | G30: 4 | H30: 5 | I30: 6 | J30: 3 | K30: 4 | L30: 7
A31: C3 | B31: A3 | D31: 5 | E31: 7 | F31: 7 | G31: 4 | H31: 5 | I31: 6 | J31: 4 | K31: 5 | L31: 6
A32: C3 | B32: A4 | D32: 5 | E32: 7 | F32: 9 | G32: 5 | H32: 6 | I32: 7 | J32: 4 | K32: 6 | L32: 7
... A36: C4 | B36: A4 | D36: 6 | E36: 8 | F36: 9 | G36: 6 | H36: 7 | I36: 8 | J36: 6 | K36: 7 | L36: 8

Sheet TOPSIS
A1: Нечёткий коллективный TOPSIS
A2: Агрегация мнений: l = min, m = среднее, u = max. FPIS = (1;1;1), FNIS = (0;0;0), вершинное расстояние.
A4: 1. Агрегированные и нормированные веса критериев
A5: Критерий | B5: l | C5: m | D5: u | E5: Множитель k | F5: u·k | G5: w (l) | H5: w (m) | I5: w (u)
A6: C1 | B6: =MIN(Оценки!D6,Оценки!G6,Оценки!J6) -> 5 | C6: =AVERAGE(Оценки!E6,Оценки!H6,Оценки!K6) -> 7 | D6: =MAX(Оценки!F6,Оценки!I6,Оценки!L6) -> 9 | E6: 1 | F6: =D6*E6 -> 9 | G6: =B6*$E6/MAX($F$6:$F$9) -> 0.55555556 | H6: =C6*$E6/MAX($F$6:$F$9) -> 0.77777778 | I6: =D6*$E6/MAX($F$6:$F$9) -> 1
A7: C2 | B7: =MIN(Оценки!D7,Оценки!G7,Оценки!J7) -> 5 | C7: =AVERAGE(Оценки!E7,Оценки!H7,Оценки!K7) -> 8.3333333 | D7: =MAX(Оценки!F7,Оценки!I7,Оценки!L7) -> 9 | E7: 1 | F7: =D7*E7 -> 9 | G7: =B7*$E7/MAX($F$6:$F$9) -> 0.55555556 | H7: =C7*$E7/MAX($F$6:$F$9) -> 0.92592593 | I7: =D7*$E7/MAX($F$6:$F$9) -> 1
A8: C3 | B8: =MIN(Оценки!D8,Оценки!G8,Оценки!J8) -> 5 | C8: =AVERAGE(Оценки!E8,Оценки!H8,Оценки!K8) -> 7 | D8: =MAX(Оценки!F8,Оценки!I8,Оценки!L8) -> 9 | E8: 1 | F8: =D8*E8 -> 9 | G8: =B8*$E8/MAX($F$6:$F$9) -> 0.55555556 | H8: =C8*$E8/MAX($F$6:$F$9) -> 0.77777778 | I8: =D8*$E8/MAX($F$6:$F$9) -> 1
A9: C4 | B9: =MIN(Оценки!D9,Оценки!G9,Оценки!J9) -> 3 | C9: =AVERAGE(Оценки!E9,Оценки!H9,Оценки!K9) -> 6.6666667 | D9: =MAX(Оценки!F9,Оценки!I9,Оценки!L9) -> 9 | E9: 1 | F9: =D9*E9 -> 9 | G9: =B9*$E9/MAX($F$6:$F$9) -> 0.33333333 | H9: =C9*$E9/MAX($F$6:$F$9) -> 0.74074074 | I9: =D9*$E9/MAX($F$6:$F$9) -> 1
A11: 2. Агрегированная нечёткая матрица решений
A12: Альт. | B12: C1 | E12: C2 | H12: C3 | K12: C4
B13: l | C13: m | D13: u | E13: l | F13: m | G13: u | H13: l | I13: m | J13: u | K13: l | L13: m | M13: u
A14: A1 | B14: =MIN(Оценки!D21,Оценки!G21,Оценки!J21) -> 4 | C14: =AVERAGE(Оценки!E21,Оценки!H21,Оценки!K21) -> 6.3333333 | D14: =MAX(Оценки!F21,Оценки!I21,Оценки!L21) -> 9 | E14: =MIN(Оценки!D25,Оценки!G25,Оценки!J25) -> 3 | F14: =AVERAGE(Оценки!E25,Оценки!H25,Оценки!K25) -> 8 | G14: =MAX(Оценки!F25,Оценки!I25,Оценки!L25) -> 9 | H14: =MIN(Оценки!D29,Оценки!G29,Оценки!J29) -> 3 | I14: =AVERAGE(Оценки!E29,Оценки!H29,Оценки!K29) -> 6.3333333 | J14: =MAX(Оценки!F29,Оценки!I29,Оценки!L29) -> 8 | K14: =MIN(Оценки!D33,Оценки!G33,Оценки!J33) -> 5 | L14: =AVERAGE(Оценки!E33,Оценки!H33,Оценки!K33) -> 8 | M14: =MAX(Оценки!F33,Оценки!I33,Оценки!L33) -> 9
A15: A2 | B15: =MIN(Оценки!D22,Оценки!G22,Оценки!J22) -> 3 | C15: =AVERAGE(Оценки!E22,Оценки!H22,Оценки!K22) -> 6.6666667 | D15: =MAX(Оценки!F22,Оценки!I22,Оценки!L22) -> 9 | E15: =MIN(Оценки!D26,Оценки!G26,Оценки!J26) -> 1 | F15: =AVERAGE(Оценки!E26,Оценки!H26,Оценки!K26) -> 4.6666667 | G15: =MAX(Оценки!F26,Оценки!I26,Оценки!L26) -> 7 | H15: =MIN(Оценки!D30,Оценки!G30,Оценки!J30) -> 2 | I15: =AVERAGE(Оценки!E30,Оценки!H30,Оценки!K30) -> 4.3333333 | J15: =MAX(Оценки!F30,Оценки!I30,Оценки!L30) -> 7 | K15: =MIN(Оценки!D34,Оценки!G34,Оценки!J34) -> 3 | L15: =AVERAGE(Оценки!E34,Оценки!H34,Оценки!K34) -> 6.6666667 | M15: =MAX(Оценки!F34,Оценки!I34,Оценки!L34) -> 9
A16: A3 | B16: =MIN(Оценки!D23,Оценки!G23,Оценки!J23) -> 1 | C16: =AVERAGE(Оценки!E23,Оценки!H23,Оценки!K23) -> 4.3333333 | D16: =MAX(Оценки!F23,Оценки!I23,Оценки!L23) -> 9 | E16: =MIN(Оценки!D27,Оценки!G27,Оценки!J27) -> 4 | F16: =AVERAGE(Оценки!E27,Оценки!H27,Оценки!K27) -> 5.6666667 | G16: =MAX(Оценки!F27,Оценки!I27,Оценки!L27) -> 8 | H16: =MIN(Оценки!D31,Оценки!G31,Оценки!J31) -> 4 | I16: =AVERAGE(Оценки!E31,Оценки!H31,Оценки!K31) -> 5.6666667 | J16: =MAX(Оценки!F31,Оценки!I31,Оценки!L31) -> 7 | K16: =MIN(Оценки!D35,Оценки!G35,Оценки!J35) -> 4 | L16: =AVERAGE(Оценки!E35,Оценки!H35,Оценки!K35) -> 6.6666667 | M16: =MAX(Оценки!F35,Оценки!I35,Оценки!L35) -> 9
A17: A4 | B17: =MIN(Оценки!D24,Оценки!G24,Оценки!J24) -> 1 | C17: =AVERAGE(Оценки!E24,Оценки!H24,Оценки!K24) -> 3.3333333 | D17: =MAX(Оценки!F24,Оценки!I24,Оценки!L24) -> 7 | E17: =MIN(Оценки!D28,Оценки!G28,Оценки!J28) -> 3 | F17: =AVERAGE(Оценки!E28,Оценки!H28,Оценки!K28) -> 5.3333333 | G17: =MAX(Оценки!F28,Оценки!I28,Оценки!L28) -> 8 | H17: =MIN(Оценки!D32,Оценки!G32,Оценки!J32) -> 4 | I17: =AVERAGE(Оценки!E32,Оценки!H32,Оценки!K32) -> 6.3333333 | J17: =MAX(Оценки!F32,Оценки!I32,Оценки!L32) -> 9 | K17: =MIN(Оценки!D36,Оценки!G36,Оценки!J36) -> 6 | L17: =AVERAGE(Оценки!E36,Оценки!H36,Оценки!K36) -> 7.3333333 | M17: =MAX(Оценки!F36,Оценки!I36,Оценки!L36) -> 9
A21: 3. Нормализованная нечёткая матрица
A22: Альт. | B22: C1 | E22: C2 | H22: C3 | K22: C4
B23: l | C23: m | D23: u | E23: l | F23: m | G23: u | H23: l | I23: m | J23: u | K23: l | L23: m | M23: u
A24: A1 | B24: =B14/MAX(D14:D17) -> 0.44444444 | C24: =C14/MAX(D14:D17) -> 0.7037037 | D24: =D14/MAX(D14:D17) -> 1 | E24: =E14/MAX(G$14:G$17) -> 0.33333333 | F24: =F14/MAX(G$14:G$17) -> 0.88888889 | G24: =G14/MAX(G$14:G$17) -> 1 | H24: =H14/MAX(J$14:J$17) -> 0.33333333 | I24: =I14/MAX(J$14:J$17) -> 0.7037037 | J24: =J14/MAX(J$14:J$17) -> 0.88888889 | K24: =K14/MAX(M$14:M$17) -> 0.55555556 | L24: =L14/MAX(M$14:M$17) -> 0.88888889 | M24: =M14/MAX(M$14:M$17) -> 1
A25: A2 | B25: =B15/MAX(D14:D17) -> 0.33333333 | C25: =C15/MAX(D14:D17) -> 0.74074074 | D25: =D15/MAX(D14:D17) -> 1 | E25: =E15/MAX(G$14:G$17) -> 0.11111111 | F25: =F15/MAX(G$14:G$17) -> 0.51851852 | G25: =G15/MAX(G$14:G$17) -> 0.77777778 | H25: =H15/MAX(J$14:J$17) -> 0.22222222 | I25: =I15/MAX(J$14:J$17) -> 0.48148148 | J25: =J15/MAX(J$14:J$17) -> 0.77777778 | K25: =K15/MAX(M$14:M$17) -> 0.33333333 | L25: =L15/MAX(M$14:M$17) -> 0.74074074 | M25: =M15/MAX(M$14:M$17) -> 1
A26: A3 | B26: =B16/MAX(D14:D17) -> 0.11111111 | C26: =C16/MAX(D14:D17) -> 0.48148148 | D26: =D16/MAX(D14:D17) -> 1 | E26: =E16/MAX(G$14:G$17) -> 0.44444444 | F26: =F16/MAX(G$14:G$17) -> 0.62962963 | G26: =G16/MAX(G$14:G$17) -> 0.88888889 | H26: =H16/MAX(J$14:J$17) -> 0.44444444 | I26: =I16/MAX(J$14:J$17) -> 0.62962963 | J26: =J16/MAX(J$14:J$17) -> 0.77777778 | K26: =K16/MAX(M$14:M$17) -> 0.44444444 | L26: =L16/MAX(M$14:M$17) -> 0.74074074 | M26: =M16/MAX(M$14:M$17) -> 1
A27: A4 | B27: =B17/MAX(D14:D17) -> 0.11111111 | C27: =C17/MAX(D14:D17) -> 0.37037037 | D27: =D17/MAX(D14:D17) -> 0.77777778 | E27: =E17/MAX(G$14:G$17) -> 0.33333333 | F27: =F17/MAX(G$14:G$17) -> 0.59259259 | G27: =G17/MAX(G$14:G$17) -> 0.88888889 | H27: =H17/MAX(J$14:J$17) -> 0.44444444 | I27: =I17/MAX(J$14:J$17) -> 0.7037037 | J27: =J17/MAX(J$14:J$17) -> 1 | K27: =K17/MAX(M$14:M$17) -> 0.66666667 | L27: =L17/MAX(M$14:M$17) -> 0.81481481 | M27: =M17/MAX(M$14:M$17) -> 1
A31: 4. Взвешенная нормализованная матрица
A32: Альт. | B32: C1 | E32: C2 | H32: C3 | K32: C4
B33: l | C33: m | D33: u | E33: l | F33: m | G33: u | H33: l | I33: m | J33: u | K33: l | L33: m | M33: u
A34: A1 | B34: =B24*$G$6 -> 0.24691358 | C34: =C24*$H$6 -> 0.5473251 | D34: =D24*$I$6 -> 1 | E34: =E24*$G$7 -> 0.18518519 | F34: =F24*$H$7 -> 0.82304527 | G34: =G24*$I$7 -> 1 | H34: =H24*$G$8 -> 0.18518519 | I34: =I24*$H$8 -> 0.5473251 | J34: =J24*$I$8 -> 0.88888889 | K34: =K24*$G$9 -> 0.18518519 | L34: =L24*$H$9 -> 0.65843621 | M34: =M24*$I$9 -> 1
A35: A2 | B35: =B25*$G$6 -> 0.18518519 | C35: =C25*$H$6 -> 0.57613169 | D35: =D25*$I$6 -> 1 | E35: =E25*$G$7 -> 0.061728395 | F35: =F25*$H$7 -> 0.48010974 | G35: =G25*$I$7 -> 0.77777778 | H35: =H25*$G$8 -> 0.12345679 | I35: =I25*$H$8 -> 0.3744856 | J35: =J25*$I$8 -> 0.77777778 | K35: =K25*$G$9 -> 0.11111111 | L35: =L25*$H$9 -> 0.54869684 | M35: =M25*$I$9 -> 1
A36: A3 | B36: =B26*$G$6 -> 0.061728395 | C36: =C26*$H$6 -> 0.3744856 | D36: =D26*$I$6 -> 1 | E36: =E26*$G$7 -> 0.24691358 | F36: =F26*$H$7 -> 0.5829904 | G36: =G26*$I$7 -> 0.88888889 | H36: =H26*$G$8 -> 0.24691358 | I36: =I26*$H$8 -> 0.48971193 | J36: =J26*$I$8 -> 0.77777778 | K36: =K26*$G$9 -> 0.14814815 | L36: =L26*$H$9 -> 0.54869684 | M36: =M26*$I$9 -> 1
A37: A4 | B37: =B27*$G$6 -> 0.061728395 | C37: =C27*$H$6 -> 0.28806584 | D37: =D27*$I$6 -> 0.77777778 | E37: =E27*$G$7 -> 0.18518519 | F37: =F27*$H$7 -> 0.54869684 | G37: =G27*$I$7 -> 0.88888889 | H37: =H27*$G$8 -> 0.24691358 | I37: =I27*$H$8 -> 0.5473251 | J37: =J27*$I$8 -> 1 | K37: =K27*$G$9 -> 0.22222222 | L37: =L27*$H$9 -> 0.60356653 | M37: =M27*$I$9 -> 1
A42: 5. Расстояния до идеальных решений и коэффициент близости
A43: Альт. | B43: d+ (до FPIS) | C43: d− (до FNIS) | D43: CC = d− / (d+ + d−) | E43: Ранг
A44: A1 | B44: =SQRT(((B34-1)^2+(C34-1)^2+(D34-1)^2)/3)+SQRT(((E34-1)^2+(F34-1)^2+(G34-1)^2)/3)+SQRT(((H34-1)^2+(I34-1)^2+(J34-1)^2)/3)+SQRT(((K34-1)^2+(L34-1)^2+(M34-1)^2)/3) -> 2.0407584 | C44: =SQRT((B34^2+C34^2+D34^2)/3)+SQRT((E34^2+F34^2+G34^2)/3)+SQRT((H34^2+I34^2+J34^2)/3)+SQRT((K34^2+L34^2+M34^2)/3) -> 2.7403686 | D44: =C44/(B44+C44) -> 0.57316373 | E44: =RANK(D44,$D$44:$D$47,0) -> 1
A45: A2 | B45: =SQRT(((B35-1)^2+(C35-1)^2+(D35-1)^2)/3)+SQRT(((E35-1)^2+(F35-1)^2+(G35-1)^2)/3)+SQRT(((H35-1)^2+(I35-1)^2+(J35-1)^2)/3)+SQRT(((K35-1)^2+(L35-1)^2+(M35-1)^2)/3) -> 2.3731148 | C45: =SQRT((B35^2+C35^2+D35^2)/3)+SQRT((E35^2+F35^2+G35^2)/3)+SQRT((H35^2+I35^2+J35^2)/3)+SQRT((K35^2+L35^2+M35^2)/3) -> 2.368883 | D45: =C45/(B45+C45) -> 0.4995538 | E45: =RANK(D45,$D$44:$D$47,0) -> 4
A46: A3 | B46: =SQRT(((B36-1)^2+(C36-1)^2+(D36-1)^2)/3)+SQRT(((E36-1)^2+(F36-1)^2+(G36-1)^2)/3)+SQRT(((H36-1)^2+(I36-1)^2+(J36-1)^2)/3)+SQRT(((K36-1)^2+(L36-1)^2+(M36-1)^2)/3) -> 2.2494093 | C46: =SQRT((B36^2+C36^2+D36^2)/3)+SQRT((E36^2+F36^2+G36^2)/3)+SQRT((H36^2+I36^2+J36^2)/3)+SQRT((K36^2+L36^2+M36^2)/3) -> 2.4611496 | D46: =C46/(B46+C46) -> 0.52247506 | E46: =RANK(D46,$D$44:$D$47,0) -> 2
A47: A4 | B47: =SQRT(((B37-1)^2+(C37-1)^2+(D37-1)^2)/3)+SQRT(((E37-1)^2+(F37-1)^2+(G37-1)^2)/3)+SQRT(((H37-1)^2+(I37-1)^2+(J37-1)^2)/3)+SQRT(((K37-1)^2+(L37-1)^2+(M37-1)^2)/3) -> 2.2448983 | C47: =SQRT((B37^2+C37^2+D37^2)/3)+SQRT((E37^2+F37^2+G37^2)/3)+SQRT((H37^2+I37^2+J37^2)/3)+SQRT((K37^2+L37^2+M37^2)/3) -> 2.4525788 | D47: =C47/(B47+C47) -> 0.52210554 | E47: =RANK(D47,$D$44:$D$47,0) -> 3

Sheet МАИ
A1: Чёткий коллективный МАИ (метод анализа иерархий)
A2: Дефаззификация PERT c=(l+4m+u)/6 → матрицы парных сравнений по шкале Саати → агрегация AIJ (среднее геометрическое) → приоритеты.
A4: 1. Чёткие оценки после дефаззификации. Важность критериев
A5: Критерий | B5: Челяпин Л. | C5: Засыпко Д. | D5: Сопельняк А.
A6: C1 | B6: =(Оценки!D6+4*Оценки!E6+Оценки!F6)/6 -> 7.8333333 | C6: =(Оценки!G6+4*Оценки!H6+Оценки!I6)/6 -> 6 | D6: =(Оценки!J6+4*Оценки!K6+Оценки!L6)/6 -> 7.3333333
A7: C2 | B7: =(Оценки!D7+4*Оценки!E7+Оценки!F7)/6 -> 8.6666667 | C7: =(Оценки!G7+4*Оценки!H7+Оценки!I7)/6 -> 8.8333333 | D7: =(Оценки!J7+4*Оценки!K7+Оценки!L7)/6 -> 6.8333333
A8: C3 | B8: =(Оценки!D8+4*Оценки!E8+Оценки!F8)/6 -> 8.5 | C8: =(Оценки!G8+4*Оценки!H8+Оценки!I8)/6 -> 6 | D8: =(Оценки!J8+4*Оценки!K8+Оценки!L8)/6 -> 6.5
A9: C4 | B9: =(Оценки!D9+4*Оценки!E9+Оценки!F9)/6 -> 4.8333333 | C9: =(Оценки!G9+4*Оценки!H9+Оценки!I9)/6 -> 7 | D9: =(Оценки!J9+4*Оценки!K9+Оценки!L9)/6 -> 8
A12: Оценки альтернатив (для затратных критериев шкала инвертируется: 10 − c)
A13: Критерий | B13: Альт. | C13: Челяпин Л. | D13: Засыпко Д. | E13: Сопельняк А.
A14: C1 | B14: A1 | C14: =IF(Оценки!$C$6="затратный",10-(Оценки!D21+4*Оценки!E21+Оценки!F21)/6,(Оценки!D21+4*Оценки!E21+Оценки!F21)/6) -> 7 | D14: =IF(Оценки!$C$6="затратный",10-(Оценки!G21+4*Оценки!H21+Оценки!I21)/6,(Оценки!G21+4*Оценки!H21+Оценки!I21)/6) -> 6.1666667 | E14: =IF(Оценки!$C$6="затратный",10-(Оценки!J21+4*Оценки!K21+Оценки!L21)/6,(Оценки!J21+4*Оценки!K21+Оценки!L21)/6) -> 5.8333333
A15: C1 | B15: A2 | C15: =IF(Оценки!$C$6="затратный",10-(Оценки!D22+4*Оценки!E22+Оценки!F22)/6,(Оценки!D22+4*Оценки!E22+Оценки!F22)/6) -> 8.6666667 | D15: =IF(Оценки!$C$6="затратный",10-(Оценки!G22+4*Оценки!H22+Оценки!I22)/6,(Оценки!G22+4*Оценки!H22+Оценки!I22)/6) -> 4.8333333 | E15: =IF(Оценки!$C$6="затратный",10-(Оценки!J22+4*Оценки!K22+Оценки!L22)/6,(Оценки!J22+4*Оценки!K22+Оценки!L22)/6) -> 5.8333333
A16: C1 | B16: A3 | C16: =IF(Оценки!$C$6="затратный",10-(Оценки!D23+4*Оценки!E23+Оценки!F23)/6,(Оценки!D23+4*Оценки!E23+Оценки!F23)/6) -> 7.8333333 | D16: =IF(Оценки!$C$6="затратный",10-(Оценки!G23+4*Оценки!H23+Оценки!I23)/6,(Оценки!G23+4*Оценки!H23+Оценки!I23)/6) -> 3.1666667 | E16: =IF(Оценки!$C$6="затратный",10-(Оценки!J23+4*Оценки!K23+Оценки!L23)/6,(Оценки!J23+4*Оценки!K23+Оценки!L23)/6) -> 2.1666667
A17: C1 | B17: A4 | C17: =IF(Оценки!$C$6="затратный",10-(Оценки!D24+4*Оценки!E24+Оценки!F24)/6,(Оценки!D24+4*Оценки!E24+Оценки!F24)/6) -> 5 | D17: =IF(Оценки!$C$6="затратный",10-(Оценки!G24+4*Оценки!H24+Оценки!I24)/6,(Оценки!G24+4*Оценки!H24+Оценки!I24)/6) -> 2 | E17: =IF(Оценки!$C$6="затратный",10-(Оценки!J24+4*Оценки!K24+Оценки!L24)/6,(Оценки!J24+4*Оценки!K24+Оценки!L24)/6) -> 3.1666667
A18: C2 | B18: A1 | C18: =IF(Оценки!$C$7="затратный",10-(Оценки!D25+4*Оценки!E25+Оценки!F25)/6,(Оценки!D25+4*Оценки!E25+Оценки!F25)/6) -> 5.6666667 | D18: =IF(Оценки!$C$7="затратный",10-(Оценки!G25+4*Оценки!H25+Оценки!I25)/6,(Оценки!G25+4*Оценки!H25+Оценки!I25)/6) -> 8.8333333 | E18: =IF(Оценки!$C$7="затратный",10-(Оценки!J25+4*Оценки!K25+Оценки!L25)/6,(Оценки!J25+4*Оценки!K25+Оценки!L25)/6) -> 8.6666667
A19: C2 | B19: A2 | C19: =IF(Оценки!$C$7="затратный",10-(Оценки!D26+4*Оценки!E26+Оценки!F26)/6,(Оценки!D26+4*Оценки!E26+Оценки!F26)/6) -> 2.8333333 | D19: =IF(Оценки!$C$7="затратный",10-(Оценки!G26+4*Оценки!H26+Оценки!I26)/6,(Оценки!G26+4*Оценки!H26+Оценки!I26)/6) -> 5 | E19: =IF(Оценки!$C$7="затратный",10-(Оценки!J26+4*Оценки!K26+Оценки!L26)/6,(Оценки!J26+4*Оценки!K26+Оценки!L26)/6) -> 5.8333333
A20: C2 | B20: A3 | C20: =IF(Оценки!$C$7="затратный",10-(Оценки!D27+4*Оценки!E27+Оценки!F27)/6,(Оценки!D27+4*Оценки!E27+Оценки!F27)/6) -> 6 | D20: =IF(Оценки!$C$7="затратный",10-(Оценки!G27+4*Оценки!H27+Оценки!I27)/6,(Оценки!G27+4*Оценки!H27+Оценки!I27)/6) -> 5.1666667 | E20: =IF(Оценки!$C$7="затратный",10-(Оценки!J27+4*Оценки!K27+Оценки!L27)/6,(Оценки!J27+4*Оценки!K27+Оценки!L27)/6) -> 6.1666667
A21: C2 | B21: A4 | C21: =IF(Оценки!$C$7="затратный",10-(Оценки!D28+4*Оценки!E28+Оценки!F28)/6,(Оценки!D28+4*Оценки!E28+Оценки!F28)/6) -> 6.8333333 | D21: =IF(Оценки!$C$7="затратный",10-(Оценки!G28+4*Оценки!H28+Оценки!I28)/6,(Оценки!G28+4*Оценки!H28+Оценки!I28)/6) -> 4.1666667 | E21: =IF(Оценки!$C$7="затратный",10-(Оценки!J28+4*Оценки!K28+Оценки!L28)/6,(Оценки!J28+4*Оценки!K28+Оценки!L28)/6) -> 5
A22: C3 | B22: A1 | C22: =IF(Оценки!$C$8="затратный",10-(Оценки!D29+4*Оценки!E29+Оценки!F29)/6,(Оценки!D29+4*Оценки!E29+Оценки!F29)/6) -> 4.6666667 | D22: =IF(Оценки!$C$8="затратный",10-(Оценки!G29+4*Оценки!H29+Оценки!I29)/6,(Оценки!G29+4*Оценки!H29+Оценки!I29)/6) -> 7 | E22: =IF(Оценки!$C$8="затратный",10-(Оценки!J29+4*Оценки!K29+Оценки!L29)/6,(Оценки!J29+4*Оценки!K29+Оценки!L29)/6) -> 7
A23: C3 | B23: A2 | C23: =IF(Оценки!$C$8="затратный",10-(Оценки!D30+4*Оценки!E30+Оценки!F30)/6,(Оценки!D30+4*Оценки!E30+Оценки!F30)/6) -> 3.8333333 | D23: =IF(Оценки!$C$8="затратный",10-(Оценки!G30+4*Оценки!H30+Оценки!I30)/6,(Оценки!G30+4*Оценки!H30+Оценки!I30)/6) -> 5 | E23: =IF(Оценки!$C$8="затратный",10-(Оценки!J30+4*Оценки!K30+Оценки!L30)/6,(Оценки!J30+4*Оценки!K30+Оценки!L30)/6) -> 4.3333333
A24: C3 | B24: A3 | C24: =IF(Оценки!$C$8="затратный",10-(Оценки!D31+4*Оценки!E31+Оценки!F31)/6,(Оценки!D31+4*Оценки!E31+Оценки!F31)/6) -> 6.6666667 | D24: =IF(Оценки!$C$8="затратный",10-(Оценки!G31+4*Оценки!H31+Оценки!I31)/6,(Оценки!G31+4*Оценки!H31+Оценки!I31)/6) -> 5 | E24: =IF(Оценки!$C$8="затратный",10-(Оценки!J31+4*Оценки!K31+Оценки!L31)/6,(Оценки!J31+4*Оценки!K31+Оценки!L31)/6) -> 5
A25: C3 | B25: A4 | C25: =IF(Оценки!$C$8="затратный",10-(Оценки!D32+4*Оценки!E32+Оценки!F32)/6,(Оценки!D32+4*Оценки!E32+Оценки!F32)/6) -> 7 | D25: =IF(Оценки!$C$8="затратный",10-(Оценки!G32+4*Оценки!H32+Оценки!I32)/6,(Оценки!G32+4*Оценки!H32+Оценки!I32)/6) -> 6 | E25: =IF(Оценки!$C$8="затратный",10-(Оценки!J32+4*Оценки!K32+Оценки!L32)/6,(Оценки!J32+4*Оценки!K32+Оценки!L32)/6) -> 5.8333333
A26: C4 | B26: A1 | C26: =IF(Оценки!$C$9="затратный",10-(Оценки!D33+4*Оценки!E33+Оценки!F33)/6,(Оценки!D33+4*Оценки!E33+Оценки!F33)/6) -> 6.6666667 | D26: =IF(Оценки!$C$9="затратный",10-(Оценки!G33+4*Оценки!H33+Оценки!I33)/6,(Оценки!G33+4*Оценки!H33+Оценки!I33)/6) -> 8 | E26: =IF(Оценки!$C$9="затратный",10-(Оценки!J33+4*Оценки!K33+Оценки!L33)/6,(Оценки!J33+4*Оценки!K33+Оценки!L33)/6) -> 8.8333333
A27: C4 | B27: A2 | C27: =IF(Оценки!$C$9="затратный",10-(Оценки!D34+4*Оценки!E34+Оценки!F34)/6,(Оценки!D34+4*Оценки!E34+Оценки!F34)/6) -> 4.8333333 | D27: =IF(Оценки!$C$9="затратный",10-(Оценки!G34+4*Оценки!H34+Оценки!I34)/6,(Оценки!G34+4*Оценки!H34+Оценки!I34)/6) -> 8 | E27: =IF(Оценки!$C$9="затратный",10-(Оценки!J34+4*Оценки!K34+Оценки!L34)/6,(Оценки!J34+4*Оценки!K34+Оценки!L34)/6) -> 7
A28: C4 | B28: A3 | C28: =IF(Оценки!$C$9="затратный",10-(Оценки!D35+4*Оценки!E35+Оценки!F35)/6,(Оценки!D35+4*Оценки!E35+Оценки!F35)/6) -> 7.5 | D28: =IF(Оценки!$C$9="затратный",10-(Оценки!G35+4*Оценки!H35+Оценки!I35)/6,(Оценки!G35+4*Оценки!H35+Оценки!I35)/6) -> 6.1666667 | E28: =IF(Оценки!$C$9="затратный",10-(Оценки!J35+4*Оценки!K35+Оценки!L35)/6,(Оценки!J35+4*Оценки!K35+Оценки!L35)/6) -> 6
A29: C4 | B29: A4 | C29: =IF(Оценки!$C$9="затратный",10-(Оценки!D36+4*Оценки!E36+Оценки!F36)/6,(Оценки!D36+4*Оценки!E36+Оценки!F36)/6) -> 7.8333333 | D29: =IF(Оценки!$C$9="затратный",10-(Оценки!G36+4*Оценки!H36+Оценки!I36)/6,(Оценки!G36+4*Оценки!H36+Оценки!I36)/6) -> 7 | E29: =IF(Оценки!$C$9="затратный",10-(Оценки!J36+4*Оценки!K36+Оценки!L36)/6,(Оценки!J36+4*Оценки!K36+Оценки!L36)/6) -> 7
A32: 2. Матрица парных сравнений критериев (групповая, AIJ)
B33: C1 | C33: C2 | D33: C3 | E33: C4 | F33: GEOMEAN | G33: Приоритет
A34: C1 | B34: 1 | C34: =(IF($B$6/$B$7>=1,MIN(ROUND($B$6/$B$7,0),9),1/MIN(ROUND($B$7/$B$6,0),9))*IF($C$6/$C$7>=1,MIN(ROUND($C$6/$C$7,0),9),1/MIN(ROUND($C$7/$C$6,0),9))*IF($D$6/$D$7>=1,MIN(ROUND($D$6/$D$7,0),9),1/MIN(ROUND($D$7/$D$6,0),9)))^(1/3) -> 1 | D34: =(IF($B$6/$B$8>=1,MIN(ROUND($B$6/$B$8,0),9),1/MIN(ROUND($B$8/$B$6,0),9))*IF($C$6/$C$8>=1,MIN(ROUND($C$6/$C$8,0),9),1/MIN(ROUND($C$8/$C$6,0),9))*IF($D$6/$D$8>=1,MIN(ROUND($D$6/$D$8,0),9),1/MIN(ROUND($D$8/$D$6,0),9)))^(1/3) -> 1 | E34: =(IF($B$6/$B$9>=1,MIN(ROUND($B$6/$B$9,0),9),1/MIN(ROUND($B$9/$B$6,0),9))*IF($C$6/$C$9>=1,MIN(ROUND($C$6/$C$9,0),9),1/MIN(ROUND($C$9/$C$6,0),9))*IF($D$6/$D$9>=1,MIN(ROUND($D$6/$D$9,0),9),1/MIN(ROUND($D$9/$D$6,0),9)))^(1/3) -> 1.259921 | F34: =GEOMEAN(B34:E34) -> 1.0594631 | G34: =F34/SUM($F$34:$F$37) -> 0.26359487
A35: C2 | B35: =(IF($B$7/$B$6>=1,MIN(ROUND($B$7/$B$6,0),9),1/MIN(ROUND($B$6/$B$7,0),9))*IF($C$7/$C$6>=1,MIN(ROUND($C$7/$C$6,0),9),1/MIN(ROUND($C$6/$C$7,0),9))*IF($D$7/$D$6>=1,MIN(ROUND($D$7/$D$6,0),9),1/MIN(ROUND($D$6/$D$7,0),9)))^(1/3) -> 1 | C35: 1 | D35: =(IF($B$7/$B$8>=1,MIN(ROUND($B$7/$B$8,0),9),1/MIN(ROUND($B$8/$B$7,0),9))*IF($C$7/$C$8>=1,MIN(ROUND($C$7/$C$8,0),9),1/MIN(ROUND($C$8/$C$7,0),9))*IF($D$7/$D$8>=1,MIN(ROUND($D$7/$D$8,0),9),1/MIN(ROUND($D$8/$D$7,0),9)))^(1/3) -> 1 | E35: =(IF($B$7/$B$9>=1,MIN(ROUND($B$7/$B$9,0),9),1/MIN(ROUND($B$9/$B$7,0),9))*IF($C$7/$C$9>=1,MIN(ROUND($C$7/$C$9,0),9),1/MIN(ROUND($C$9/$C$7,0),9))*IF($D$7/$D$9>=1,MIN(ROUND($D$7/$D$9,0),9),1/MIN(ROUND($D$9/$D$7,0),9)))^(1/3) -> 1.259921 | F35: =GEOMEAN(B35:E35) -> 1.0594631 | G35: =F35/SUM($F$34:$F$37) -> 0.26359487
A36: C3 | B36: =(IF($B$8/$B$6>=1,MIN(ROUND($B$8/$B$6,0),9),1/MIN(ROUND($B$6/$B$8,0),9))*IF($C$8/$C$6>=1,MIN(ROUND($C$8/$C$6,0),9),1/MIN(ROUND($C$6/$C$8,0),9))*IF($D$8/$D$6>=1,MIN(ROUND($D$8/$D$6,0),9),1/MIN(ROUND($D$6/$D$8,0),9)))^(1/3) -> 1 | C36: =(IF($B$8/$B$7>=1,MIN(ROUND($B$8/$B$7,0),9),1/MIN(ROUND($B$7/$B$8,0),9))*IF($C$8/$C$7>=1,MIN(ROUND($C$8/$C$7,0),9),1/MIN(ROUND($C$7/$C$8,0),9))*IF($D$8/$D$7>=1,MIN(ROUND($D$8/$D$7,0),9),1/MIN(ROUND($D$7/$D$8,0),9)))^(1/3) -> 1 | D36: 1 | E36: =(IF($B$8/$B$9>=1,MIN(ROUND($B$8/$B$9,0),9),1/MIN(ROUND($B$9/$B$8,0),9))*IF($C$8/$C$9>=1,MIN(ROUND($C$8/$C$9,0),9),1/MIN(ROUND($C$9/$C$8,0),9))*IF($D$8/$D$9>=1,MIN(ROUND($D$8/$D$9,0),9),1/MIN(ROUND($D$9/$D$8,0),9)))^(1/3) -> 1.259921 | F36: =GEOMEAN(B36:E36) -> 1.0594631 | G36: =F36/SUM($F$34:$F$37) -> 0.26359487
A37: C4 | B37: =(IF($B$9/$B$6>=1,MIN(ROUND($B$9/$B$6,0),9),1/MIN(ROUND($B$6/$B$9,0),9))*IF($C$9/$C$6>=1,MIN(ROUND($C$9/$C$6,0),9),1/MIN(ROUND($C$6/$C$9,0),9))*IF($D$9/$D$6>=1,MIN(ROUND($D$9/$D$6,0),9),1/MIN(ROUND($D$6/$D$9,0),9)))^(1/3) -> 0.79370053 | C37: =(IF($B$9/$B$7>=1,MIN(ROUND($B$9/$B$7,0),9),1/MIN(ROUND($B$7/$B$9,0),9))*IF($C$9/$C$7>=1,MIN(ROUND($C$9/$C$7,0),9),1/MIN(ROUND($C$7/$C$9,0),9))*IF($D$9/$D$7>=1,MIN(ROUND($D$9/$D$7,0),9),1/MIN(ROUND($D$7/$D$9,0),9)))^(1/3) -> 0.79370053 | D37: =(IF($B$9/$B$8>=1,MIN(ROUND($B$9/$B$8,0),9),1/MIN(ROUND($B$8/$B$9,0),9))*IF($C$9/$C$8>=1,MIN(ROUND($C$9/$C$8,0),9),1/MIN(ROUND($C$8/$C$9,0),9))*IF($D$9/$D$8>=1,MIN(ROUND($D$9/$D$8,0),9),1/MIN(ROUND($D$8/$D$9,0),9)))^(1/3) -> 0.79370053 | E37: 1 | F37: =GEOMEAN(B37:E37) -> 0.84089642 | G37: =F37/SUM($F$34:$F$37) -> 0.20921539
A38: Σ столбца | B38: =SUM(B34:B37) -> 3.7937005 | C38: =SUM(C34:C37) -> 3.7937005 | D38: =SUM(D34:D37) -> 3.7937005 | E38: =SUM(E34:E37) -> 4.7797631
A39: w (гориз.) | B39: =G34 -> 0.26359487 | C39: =G35 -> 0.26359487 | D39: =G36 -> 0.26359487 | E39: =G37 -> 0.20921539
A40: λmax | B40: =SUMPRODUCT(B38:E38,B39:E39) -> 4 | C40: CI | D40: =(B40-4)/3 -> 0 | E40: CR | F40: =D40/0.9 -> 0 | G40: =IF(F40<0.1,"согласована","требует пересмотра") -> согласована
A42: Матрица парных сравнений альтернатив по критерию C1 — Зависимость от внешних источников данных и интеграций
B43: A1 | C43: A2 | D43: A3 | E43: A4 | F43: GEOMEAN | G43: Приоритет
A44: A1 | B44: 1 | C44: =(IF($C$14/$C$15>=1,MIN(ROUND($C$14/$C$15,0),9),1/MIN(ROUND($C$15/$C$14,0),9))*IF($D$14/$D$15>=1,MIN(ROUND($D$14/$D$15,0),9),1/MIN(ROUND($D$15/$D$14,0),9))*IF($E$14/$E$15>=1,MIN(ROUND($E$14/$E$15,0),9),1/MIN(ROUND($E$15/$E$14,0),9)))^(1/3) -> 1 | D44: =(IF($C$14/$C$16>=1,MIN(ROUND($C$14/$C$16,0),9),1/MIN(ROUND($C$16/$C$14,0),9))*IF($D$14/$D$16>=1,MIN(ROUND($D$14/$D$16,0),9),1/MIN(ROUND($D$16/$D$14,0),9))*IF($E$14/$E$16>=1,MIN(ROUND($E$14/$E$16,0),9),1/MIN(ROUND($E$16/$E$14,0),9)))^(1/3) -> 1.8171206 | E44: =(IF($C$14/$C$17>=1,MIN(ROUND($C$14/$C$17,0),9),1/MIN(ROUND($C$17/$C$14,0),9))*IF($D$14/$D$17>=1,MIN(ROUND($D$14/$D$17,0),9),1/MIN(ROUND($D$17/$D$14,0),9))*IF($E$14/$E$17>=1,MIN(ROUND($E$14/$E$17,0),9),1/MIN(ROUND($E$17/$E$14,0),9)))^(1/3) -> 1.8171206 | F44: =GEOMEAN(B44:E44) -> 1.3480062 | G44: =F44/SUM($F$44:$F$47) -> 0.32044664
A45: A2 | B45: =(IF($C$15/$C$14>=1,MIN(ROUND($C$15/$C$14,0),9),1/MIN(ROUND($C$14/$C$15,0),9))*IF($D$15/$D$14>=1,MIN(ROUND($D$15/$D$14,0),9),1/MIN(ROUND($D$14/$D$15,0),9))*IF($E$15/$E$14>=1,MIN(ROUND($E$15/$E$14,0),9),1/MIN(ROUND($E$14/$E$15,0),9)))^(1/3) -> 1 | C45: 1 | D45: =(IF($C$15/$C$16>=1,MIN(ROUND($C$15/$C$16,0),9),1/MIN(ROUND($C$16/$C$15,0),9))*IF($D$15/$D$16>=1,MIN(ROUND($D$15/$D$16,0),9),1/MIN(ROUND($D$16/$D$15,0),9))*IF($E$15/$E$16>=1,MIN(ROUND($E$15/$E$16,0),9),1/MIN(ROUND($E$16/$E$15,0),9)))^(1/3) -> 1.8171206 | E45: =(IF($C$15/$C$17>=1,MIN(ROUND($C$15/$C$17,0),9),1/MIN(ROUND($C$17/$C$15,0),9))*IF($D$15/$D$17>=1,MIN(ROUND($D$15/$D$17,0),9),1/MIN(ROUND($D$17/$D$15,0),9))*IF($E$15/$E$17>=1,MIN(ROUND($E$15/$E$17,0),9),1/MIN(ROUND($E$17/$E$15,0),9)))^(1/3) -> 2 | F45: =GEOMEAN(B45:E45) -> 1.3807131 | G45: =F45/SUM($F$44:$F$47) -> 0.3282217
A46: A3 | B46: =(IF($C$16/$C$14>=1,MIN(ROUND($C$16/$C$14,0),9),1/MIN(ROUND($C$14/$C$16,0),9))*IF($D$16/$D$14>=1,MIN(ROUND($D$16/$D$14,0),9),1/MIN(ROUND($D$14/$D$16,0),9))*IF($E$16/$E$14>=1,MIN(ROUND($E$16/$E$14,0),9),1/MIN(ROUND($E$14/$E$16,0),9)))^(1/3) -> 0.55032121 | C46: =(IF($C$16/$C$15>=1,MIN(ROUND($C$16/$C$15,0),9),1/MIN(ROUND($C$15/$C$16,0),9))*IF($D$16/$D$15>=1,MIN(ROUND($D$16/$D$15,0),9),1/MIN(ROUND($D$15/$D$16,0),9))*IF($E$16/$E$15>=1,MIN(ROUND($E$16/$E$15,0),9),1/MIN(ROUND($E$15/$E$16,0),9)))^(1/3) -> 0.55032121 | D46: 1 | E46: =(IF($C$16/$C$17>=1,MIN(ROUND($C$16/$C$17,0),9),1/MIN(ROUND($C$17/$C$16,0),9))*IF($D$16/$D$17>=1,MIN(ROUND($D$16/$D$17,0),9),1/MIN(ROUND($D$17/$D$16,0),9))*IF($E$16/$E$17>=1,MIN(ROUND($E$16/$E$17,0),9),1/MIN(ROUND($E$17/$E$16,0),9)))^(1/3) -> 1.5874011 | F46: =GEOMEAN(B46:E46) -> 0.83268318 | G46: =F46/SUM($F$44:$F$47) -> 0.19794459
...

Sheet Итог
A1: Сводное сравнение методов
A3: Альт. | B3: Концепция | C3: CC (TOPSIS) | D3: Ранг TOPSIS | E3: Приоритет (МАИ) | F3: Ранг МАИ
A4: A1 | B4: Общие подписки и бытовые расходы соседей по квартире | C4: =TOPSIS!D44 -> 0.57316373 | D4: =TOPSIS!E44 -> 1 | E4: =МАИ!F87 -> 0.28856873 | F4: =МАИ!G87 -> 1
A5: A2 | B5: Трекер поломок и ремонтов вещей («паспорт вещи») | C5: =TOPSIS!D45 -> 0.4995538 | D5: =TOPSIS!E45 -> 4 | E5: =МАИ!F88 -> 0.23947424 | F5: =МАИ!G88 -> 3
A6: A3 | B6: FocusFlow — планировщик задач по правилам тайм-менеджмента | C6: =TOPSIS!D46 -> 0.52247506 | D6: =TOPSIS!E46 -> 2 | E6: =МАИ!F89 -> 0.24160351 | F6: =МАИ!G89 -> 2
A7: A4 | B7: Система контроля версий для текстовых документов | C7: =TOPSIS!D47 -> 0.52210554 | D7: =TOPSIS!E47 -> 3 | E7: =МАИ!F90 -> 0.23035353 | F7: =МАИ!G90 -> 4
A9: Победитель по TOPSIS: | C9: =INDEX($A$4:$A$7,MATCH(1,$D$4:$D$7,0)) -> A1
A10: Победитель по МАИ: | C10: =INDEX($A$4:$A$7,MATCH(1,$F$4:$F$7,0)) -> A1
